<?xml version="1.0"?>
<robot name="UR3">
    <link name="robot_base">
        <collision name="UR3">
            <origin xyz="-0.000000 -0.000000 -0.000000" rpy="-3.141593 3.141593 -3.141593" />
            <geometry>
                <mesh filename="../urdf_ur3/ur3_robot_base_coll_1.dae" />
            </geometry>
        </collision>
        <visual name="link1_visible">
            <origin xyz="-0.000000 -0.000000 -0.000000" rpy="-3.141593 3.141593 -3.141593" />
            <geometry>
                <mesh filename="../urdf_ur3/ur3_link1_visible_vis_1.dae" />
            </geometry>
            <material name="link1_visible_material">
                <color rgba="0.870588 0.870588 0.870588 1.0" />
            </material>
        </visual>
        <visual name="link1_visible">
            <origin xyz="-0.000000 -0.000000 -0.000000" rpy="-3.141593 3.141593 -3.141593" />
            <geometry>
                <mesh filename="../urdf_ur3/ur3_link1_visible_vis_2.dae" />
            </geometry>
            <material name="link1_visible_material">
                <color rgba="0.282353 0.282353 0.282353 1.0" />
            </material>
        </visual>
    </link>
    <joint name="joint1" type="revolute">
        <axis xyz="0 0 1" />
        <limit upper="6.2831854820251" lower="-6.2831854820251" effort="50.0" velocity="3.1415927410126" />
        <parent link="robot_base" />
        <child link="link" />
        <origin xyz="0.000000 0.000000 0.000000" rpy="-3.141593 3.141593 0.000000" />
    </joint>
    <link name="link">
        <inertial>
            <origin xyz="0.000004 0.006743 0.145671" rpy="-3.141593 3.141593 1.570796" />
            <inertia iyy="0.01409502211253" ixz="0.00033951027518348" iyz="1.1680027939965e-06" izz="0.0099350964551032" ixy="2.844135051548e-09" ixx="0.013322851015861" />
            <mass value="1.0" />
        </inertial>
        <collision name="link">
            <origin xyz="0.000000 0.000000 0.000000" rpy="3.141593 3.141593 -0.000000" />
            <geometry>
                <mesh filename="../urdf_ur3/ur3_link_coll_1.dae" />
            </geometry>
        </collision>
        <visual name="link2_visible">
            <origin xyz="0.000000 0.000000 0.000000" rpy="3.141593 3.141593 -0.000000" />
            <geometry>
                <mesh filename="../urdf_ur3/ur3_link2_visible_vis_1.dae" />
            </geometry>
            <material name="link2_visible_material">
                <color rgba="0.535294 0.535294 0.535294 1.0" />
            </material>
        </visual>
        <visual name="link2_visible">
            <origin xyz="0.000000 0.000000 0.000000" rpy="3.141593 3.141593 -0.000000" />
            <geometry>
                <mesh filename="../urdf_ur3/ur3_link2_visible_vis_2.dae" />
            </geometry>
            <material name="link2_visible_material">
                <color rgba="0.508235 0.761224 0.903529 1.0" />
            </material>
        </visual>
        <visual name="link2_visible">
            <origin xyz="0.000000 0.000000 0.000000" rpy="3.141593 3.141593 -0.000000" />
            <geometry>
                <mesh filename="../urdf_ur3/ur3_link2_visible_vis_3.dae" />
            </geometry>
            <material name="link2_visible_material">
                <color rgba="0.535294 0.535294 0.535294 1.0" />
            </material>
        </visual>
        <visual name="link2_visible">
            <origin xyz="0.000000 0.000000 0.000000" rpy="3.141593 3.141593 -0.000000" />
            <geometry>
                <mesh filename="../urdf_ur3/ur3_link2_visible_vis_4.dae" />
            </geometry>
            <material name="link2_visible_material">
                <color rgba="0.282353 0.282353 0.282353 1.0" />
            </material>
        </visual>
    </link>
    <joint name="joint2" type="revolute">
        <axis xyz="0 0 1" />
        <limit upper="6.2831854820251" lower="-6.2831854820251" effort="50.0" velocity="3.1415927410126" />
        <parent link="link" />
        <child link="link_2" />
        <origin xyz="0.000054 0.111541 0.151899" rpy="1.570795 3.141593 -3.141593" />
    </joint>
    <link name="link_2">
        <inertial>
            <origin xyz="0.000069 -0.108116 0.006647" rpy="1.570796 1.570796 0.000000" />
            <inertia iyy="0.18813148649674" ixz="0.0079891854119392" iyz="4.695736461373e-05" izz="0.03454149621641" ixy="1.4690480381395e-05" ixx="0.17734117337558" />
            <mass value="2.5" />
        </inertial>
        <collision name="link">
            <origin xyz="-0.000054 0.151899 -0.111541" rpy="1.570795 3.141593 0.000000" />
            <geometry>
                <mesh filename="../urdf_ur3/ur3_link_2_coll_1.dae" />
            </geometry>
        </collision>
        <collision name="link">
            <origin xyz="-0.000054 0.151899 -0.111541" rpy="1.570795 3.141593 0.000000" />
            <geometry>
                <mesh filename="../urdf_ur3/ur3_link_2_coll_2.dae" />
            </geometry>
        </collision>
        <collision name="link">
            <origin xyz="-0.000054 0.151899 -0.111541" rpy="1.570795 3.141593 0.000000" />
            <geometry>
                <mesh filename="../urdf_ur3/ur3_link_2_coll_3.dae" />
            </geometry>
        </collision>
        <collision name="link">
            <origin xyz="-0.000054 0.151899 -0.111541" rpy="1.570795 3.141593 0.000000" />
            <geometry>
                <mesh filename="../urdf_ur3/ur3_link_2_coll_4.dae" />
            </geometry>
        </collision>
        <collision name="link">
            <origin xyz="-0.000054 0.151899 -0.111541" rpy="1.570795 3.141593 0.000000" />
            <geometry>
                <mesh filename="../urdf_ur3/ur3_link_2_coll_5.dae" />
            </geometry>
        </collision>
        <visual name="link3_visible">
            <origin xyz="-0.000054 0.151899 -0.111541" rpy="1.570795 3.141593 0.000000" />
            <geometry>
                <mesh filename="../urdf_ur3/ur3_link3_visible_vis_1.dae" />
            </geometry>
            <material name="link3_visible_material">
                <color rgba="0.870588 0.870588 0.870588 1.0" />
            </material>
        </visual>
        <visual name="link3_visible">
            <origin xyz="-0.000054 0.151899 -0.111541" rpy="1.570795 3.141593 0.000000" />
            <geometry>
                <mesh filename="../urdf_ur3/ur3_link3_visible_vis_2.dae" />
            </geometry>
            <material name="link3_visible_material">
                <color rgba="0.282353 0.282353 0.282353 1.0" />
            </material>
        </visual>
        <visual name="link3_visible">
            <origin xyz="-0.000054 0.151899 -0.111541" rpy="1.570795 3.141593 0.000000" />
            <geometry>
                <mesh filename="../urdf_ur3/ur3_link3_visible_vis_3.dae" />
            </geometry>
            <material name="link3_visible_material">
                <color rgba="0.282353 0.282353 0.282353 1.0" />
            </material>
        </visual>
        <visual name="link3_visible">
            <origin xyz="-0.000054 0.151899 -0.111541" rpy="1.570795 3.141593 0.000000" />
            <geometry>
                <mesh filename="../urdf_ur3/ur3_link3_visible_vis_4.dae" />
            </geometry>
            <material name="link3_visible_material">
                <color rgba="0.535294 0.535294 0.535294 1.0" />
            </material>
        </visual>
        <visual name="link3_visible">
            <origin xyz="-0.000054 0.151899 -0.111541" rpy="1.570795 3.141593 0.000000" />
            <geometry>
                <mesh filename="../urdf_ur3/ur3_link3_visible_vis_5.dae" />
            </geometry>
            <material name="link3_visible_material">
                <color rgba="0.282353 0.282353 0.282353 1.0" />
            </material>
        </visual>
        <visual name="link3_visible">
            <origin xyz="-0.000054 0.151899 -0.111541" rpy="1.570795 3.141593 0.000000" />
            <geometry>
                <mesh filename="../urdf_ur3/ur3_link3_visible_vis_6.dae" />
            </geometry>
            <material name="link3_visible_material">
                <color rgba="0.535294 0.535294 0.535294 1.0" />
            </material>
        </visual>
        <visual name="link3_visible">
            <origin xyz="-0.000054 0.151899 -0.111541" rpy="1.570795 3.141593 0.000000" />
            <geometry>
                <mesh filename="../urdf_ur3/ur3_link3_visible_vis_7.dae" />
            </geometry>
            <material name="link3_visible_material">
                <color rgba="0.508235 0.761224 0.903529 1.0" />
            </material>
        </visual>
        <visual name="link3_visible">
            <origin xyz="-0.000054 0.151899 -0.111541" rpy="1.570795 3.141593 0.000000" />
            <geometry>
                <mesh filename="../urdf_ur3/ur3_link3_visible_vis_8.dae" />
            </geometry>
            <material name="link3_visible_material">
                <color rgba="0.535294 0.535294 0.535294 1.0" />
            </material>
        </visual>
        <visual name="link3_visible">
            <origin xyz="-0.000054 0.151899 -0.111541" rpy="1.570795 3.141593 0.000000" />
            <geometry>
                <mesh filename="../urdf_ur3/ur3_link3_visible_vis_9.dae" />
            </geometry>
            <material name="link3_visible_material">
                <color rgba="0.535294 0.535294 0.535294 1.0" />
            </material>
        </visual>
        <visual name="link3_visible">
            <origin xyz="-0.000054 0.151899 -0.111541" rpy="1.570795 3.141593 0.000000" />
            <geometry>
                <mesh filename="../urdf_ur3/ur3_link3_visible_vis_10.dae" />
            </geometry>
            <material name="link3_visible_material">
                <color rgba="0.508235 0.761224 0.903529 1.0" />
            </material>
        </visual>
    </link>
    <joint name="joint3" type="revolute">
        <axis xyz="0 0 1" />
        <limit upper="6.2831854820251" lower="-6.2831854820251" effort="50.0" velocity="3.1415927410126" />
        <parent link="link_2" />
        <child link="link_3" />
        <origin xyz="0.000076 -0.243650 -0.000000" rpy="-3.141593 3.141593 -3.141593" />
    </joint>
    <link name="link_3">
        <inertial>
            <origin xyz="-0.000100 -0.117175 -0.077228" rpy="1.570796 1.570796 0.000000" />
            <inertia iyy="0.12850853130719" ixz="-0.0073093291977017" iyz="-2.1974749022959e-05" izz="0.019407330650231" ixy="-2.2961357759829e-05" ixx="0.12383162690089" />
            <mass value="2.5" />
        </inertial>
        <collision name="link">
            <origin xyz="-0.000130 0.395549 -0.111541" rpy="1.570795 3.141593 0.000000" />
            <geometry>
                <mesh filename="../urdf_ur3/ur3_link_3_coll_1.dae" />
            </geometry>
        </collision>
        <collision name="link">
            <origin xyz="-0.000130 0.395549 -0.111541" rpy="1.570795 3.141593 0.000000" />
            <geometry>
                <mesh filename="../urdf_ur3/ur3_link_3_coll_2.dae" />
            </geometry>
        </collision>
        <collision name="link">
            <origin xyz="-0.000130 0.395549 -0.111541" rpy="1.570795 3.141593 0.000000" />
            <geometry>
                <mesh filename="../urdf_ur3/ur3_link_3_coll_3.dae" />
            </geometry>
        </collision>
        <collision name="link">
            <origin xyz="-0.000130 0.395549 -0.111541" rpy="1.570795 3.141593 0.000000" />
            <geometry>
                <mesh filename="../urdf_ur3/ur3_link_3_coll_4.dae" />
            </geometry>
        </collision>
        <collision name="link">
            <origin xyz="-0.000130 0.395549 -0.111541" rpy="1.570795 3.141593 0.000000" />
            <geometry>
                <mesh filename="../urdf_ur3/ur3_link_3_coll_5.dae" />
            </geometry>
        </collision>
        <visual name="link4_visible">
            <origin xyz="-0.000130 0.395549 -0.111541" rpy="1.570795 3.141593 0.000000" />
            <geometry>
                <mesh filename="../urdf_ur3/ur3_link4_visible_vis_1.dae" />
            </geometry>
            <material name="link4_visible_material">
                <color rgba="0.870588 0.870588 0.870588 1.0" />
            </material>
        </visual>
        <visual name="link4_visible">
            <origin xyz="-0.000130 0.395549 -0.111541" rpy="1.570795 3.141593 0.000000" />
            <geometry>
                <mesh filename="../urdf_ur3/ur3_link4_visible_vis_2.dae" />
            </geometry>
            <material name="link4_visible_material">
                <color rgba="0.282353 0.282353 0.282353 1.0" />
            </material>
        </visual>
        <visual name="link4_visible">
            <origin xyz="-0.000130 0.395549 -0.111541" rpy="1.570795 3.141593 0.000000" />
            <geometry>
                <mesh filename="../urdf_ur3/ur3_link4_visible_vis_3.dae" />
            </geometry>
            <material name="link4_visible_material">
                <color rgba="0.282353 0.282353 0.282353 1.0" />
            </material>
        </visual>
        <visual name="link4_visible">
            <origin xyz="-0.000130 0.395549 -0.111541" rpy="1.570795 3.141593 0.000000" />
            <geometry>
                <mesh filename="../urdf_ur3/ur3_link4_visible_vis_4.dae" />
            </geometry>
            <material name="link4_visible_material">
                <color rgba="0.535294 0.535294 0.535294 1.0" />
            </material>
        </visual>
        <visual name="link4_visible">
            <origin xyz="-0.000130 0.395549 -0.111541" rpy="1.570795 3.141593 0.000000" />
            <geometry>
                <mesh filename="../urdf_ur3/ur3_link4_visible_vis_5.dae" />
            </geometry>
            <material name="link4_visible_material">
                <color rgba="0.282353 0.282353 0.282353 1.0" />
            </material>
        </visual>
        <visual name="link4_visible">
            <origin xyz="-0.000130 0.395549 -0.111541" rpy="1.570795 3.141593 0.000000" />
            <geometry>
                <mesh filename="../urdf_ur3/ur3_link4_visible_vis_6.dae" />
            </geometry>
            <material name="link4_visible_material">
                <color rgba="0.508235 0.761224 0.903529 1.0" />
            </material>
        </visual>
        <visual name="link4_visible">
            <origin xyz="-0.000130 0.395549 -0.111541" rpy="1.570795 3.141593 0.000000" />
            <geometry>
                <mesh filename="../urdf_ur3/ur3_link4_visible_vis_7.dae" />
            </geometry>
            <material name="link4_visible_material">
                <color rgba="0.535294 0.535294 0.535294 1.0" />
            </material>
        </visual>
        <visual name="link4_visible">
            <origin xyz="-0.000130 0.395549 -0.111541" rpy="1.570795 3.141593 0.000000" />
            <geometry>
                <mesh filename="../urdf_ur3/ur3_link4_visible_vis_8.dae" />
            </geometry>
            <material name="link4_visible_material">
                <color rgba="0.535294 0.535294 0.535294 1.0" />
            </material>
        </visual>
        <visual name="link4_visible">
            <origin xyz="-0.000130 0.395549 -0.111541" rpy="1.570795 3.141593 0.000000" />
            <geometry>
                <mesh filename="../urdf_ur3/ur3_link4_visible_vis_9.dae" />
            </geometry>
            <material name="link4_visible_material">
                <color rgba="0.282353 0.282353 0.282353 1.0" />
            </material>
        </visual>
    </link>
    <joint name="joint4" type="revolute">
        <axis xyz="0 0 1" />
        <limit upper="6.2831854820251" lower="-6.2831854820251" effort="50.0" velocity="6.2831854820251" />
        <parent link="link_3" />
        <child link="link_4" />
        <origin xyz="-0.000045 -0.213250 -0.000001" rpy="-3.141591 3.141593 3.141593" />
    </joint>
    <link name="link_4">
        <inertial>
            <origin xyz="-0.000063 -0.002676 -0.002551" rpy="1.570796 1.570796 0.000000" />
            <inertia iyy="0.0076237864851809" ixz="4.4444737658457e-05" iyz="1.9329876560889e-05" izz="0.0046337627007229" ixy="-1.3022311240541e-06" ixx="0.0074607414118797" />
            <mass value="1.0" />
        </inertial>
        <collision name="link">
            <origin xyz="-0.000085 0.608799 -0.111541" rpy="1.570796 3.141593 -0.000000" />
            <geometry>
                <mesh filename="../urdf_ur3/ur3_link_4_coll_1.dae" />
            </geometry>
        </collision>
        <visual name="link5_visible">
            <origin xyz="-0.000085 0.608799 -0.111541" rpy="1.570796 3.141593 -0.000000" />
            <geometry>
                <mesh filename="../urdf_ur3/ur3_link5_visible_vis_1.dae" />
            </geometry>
            <material name="link5_visible_material">
                <color rgba="0.535294 0.535294 0.535294 1.0" />
            </material>
        </visual>
        <visual name="link5_visible">
            <origin xyz="-0.000085 0.608799 -0.111541" rpy="1.570796 3.141593 -0.000000" />
            <geometry>
                <mesh filename="../urdf_ur3/ur3_link5_visible_vis_2.dae" />
            </geometry>
            <material name="link5_visible_material">
                <color rgba="0.535294 0.535294 0.535294 1.0" />
            </material>
        </visual>
        <visual name="link5_visible">
            <origin xyz="-0.000085 0.608799 -0.111541" rpy="1.570796 3.141593 -0.000000" />
            <geometry>
                <mesh filename="../urdf_ur3/ur3_link5_visible_vis_3.dae" />
            </geometry>
            <material name="link5_visible_material">
                <color rgba="0.508235 0.761224 0.903529 1.0" />
            </material>
        </visual>
        <visual name="link5_visible">
            <origin xyz="-0.000085 0.608799 -0.111541" rpy="1.570796 3.141593 -0.000000" />
            <geometry>
                <mesh filename="../urdf_ur3/ur3_link5_visible_vis_4.dae" />
            </geometry>
            <material name="link5_visible_material">
                <color rgba="0.282353 0.282353 0.282353 1.0" />
            </material>
        </visual>
    </link>
    <joint name="joint5" type="revolute">
        <axis xyz="0 0 1" />
        <limit upper="6.2831854820251" lower="-6.2831854820251" effort="50.0" velocity="6.2831854820251" />
        <parent link="link_4" />
        <child link="link_5" />
        <origin xyz="-0.000000 -0.084218 0.000684" rpy="-1.570796 3.141593 -3.141593" />
    </joint>
    <link name="link_5">
        <inertial>
            <origin xyz="0.000520 0.003355 -0.001879" rpy="-3.141593 3.141593 1.570796" />
            <inertia iyy="0.0077851674584931" ixz="7.4333852122585e-05" iyz="-2.5701652848516e-06" izz="0.0076031188661991" ixy="1.0248622227352e-05" ixx="0.0046708090457454" />
            <mass value="1.0" />
        </inertial>
        <collision name="link">
            <origin xyz="-0.000085 -0.112225 -0.693017" rpy="3.141593 3.141593 -0.000000" />
            <geometry>
                <mesh filename="../urdf_ur3/ur3_link_5_coll_1.dae" />
            </geometry>
        </collision>
        <visual name="link6_visible">
            <origin xyz="-0.000085 -0.112225 -0.693017" rpy="3.141593 3.141593 -0.000000" />
            <geometry>
                <mesh filename="../urdf_ur3/ur3_link6_visible_vis_1.dae" />
            </geometry>
            <material name="link6_visible_material">
                <color rgba="0.535294 0.535294 0.535294 1.0" />
            </material>
        </visual>
        <visual name="link6_visible">
            <origin xyz="-0.000085 -0.112225 -0.693017" rpy="3.141593 3.141593 -0.000000" />
            <geometry>
                <mesh filename="../urdf_ur3/ur3_link6_visible_vis_2.dae" />
            </geometry>
            <material name="link6_visible_material">
                <color rgba="0.535294 0.535294 0.535294 1.0" />
            </material>
        </visual>
        <visual name="link6_visible">
            <origin xyz="-0.000085 -0.112225 -0.693017" rpy="3.141593 3.141593 -0.000000" />
            <geometry>
                <mesh filename="../urdf_ur3/ur3_link6_visible_vis_3.dae" />
            </geometry>
            <material name="link6_visible_material">
                <color rgba="0.508235 0.761224 0.903529 1.0" />
            </material>
        </visual>
        <visual name="link6_visible">
            <origin xyz="-0.000085 -0.112225 -0.693017" rpy="3.141593 3.141593 -0.000000" />
            <geometry>
                <mesh filename="../urdf_ur3/ur3_link6_visible_vis_4.dae" />
            </geometry>
            <material name="link6_visible_material">
                <color rgba="0.282353 0.282353 0.282353 1.0" />
            </material>
        </visual>
    </link>
    <joint name="joint6" type="continuous">
        <axis xyz="0 0 1" />
        <parent link="link_5" />
        <child link="link_6" />
        <origin xyz="-0.000000 -0.000684 0.001132" rpy="1.570796 3.141593 -3.141593" />
    </joint>
    <link name="link_6">
        <collision name="link">
            <origin xyz="0.000095 -0.000194 0.066355" rpy="-0.000000 3.141593 -3.141593" />
            <geometry>
                <cylinder radius="0.03120630979538" length="0.032068222761154" />
            </geometry>
        </collision>
        <visual name="link7_visible">
            <origin xyz="-0.000085 0.694149 -0.111541" rpy="1.570796 3.141593 -0.000000" />
            <geometry>
                <mesh filename="../urdf_ur3/ur3_link7_visible_vis_1.dae" />
            </geometry>
            <material name="link7_visible_material">
                <color rgba="0.870588 0.870588 0.870588 1.0" />
            </material>
        </visual>
        <visual name="link7_visible">
            <origin xyz="-0.000085 0.694149 -0.111541" rpy="1.570796 3.141593 -0.000000" />
            <geometry>
                <mesh filename="../urdf_ur3/ur3_link7_visible_vis_2.dae" />
            </geometry>
            <material name="link7_visible_material">
                <color rgba="0.870588 0.870588 0.870588 1.0" />
            </material>
        </visual>
    </link>
</robot>
